[2023-10-28T21:09:21.171+0500] {taskinstance.py:1159} INFO - Dependencies all met for dep_context=non-requeueable deps ti=<TaskInstance: youtube_comments_score.get_data manual__2023-10-28T15:39:44.500439+00:00 [queued]>
[2023-10-28T21:09:21.175+0500] {taskinstance.py:1159} INFO - Dependencies all met for dep_context=requeueable deps ti=<TaskInstance: youtube_comments_score.get_data manual__2023-10-28T15:39:44.500439+00:00 [queued]>
[2023-10-28T21:09:21.175+0500] {taskinstance.py:1361} INFO - Starting attempt 2 of 2
[2023-10-28T21:09:21.186+0500] {taskinstance.py:1382} INFO - Executing <Task(BashOperator): get_data> on 2023-10-28 15:39:44.500439+00:00
[2023-10-28T21:09:21.188+0500] {standard_task_runner.py:57} INFO - Started process 6845 to run task
[2023-10-28T21:09:21.191+0500] {standard_task_runner.py:84} INFO - Running: ['airflow', 'tasks', 'run', 'youtube_comments_score', 'get_data', 'manual__2023-10-28T15:39:44.500439+00:00', '--job-id', '10', '--raw', '--subdir', 'DAGS_FOLDER/youtube_comments_score.py', '--cfg-path', '/tmp/tmpj8_rfda6']
[2023-10-28T21:09:21.192+0500] {standard_task_runner.py:85} INFO - Job 10: Subtask get_data
[2023-10-28T21:09:21.219+0500] {task_command.py:416} INFO - Running <TaskInstance: youtube_comments_score.get_data manual__2023-10-28T15:39:44.500439+00:00 [running]> on host xFlow.xFlow.virtualbox.org
[2023-10-28T21:09:21.262+0500] {taskinstance.py:1662} INFO - Exporting env vars: AIRFLOW_CTX_DAG_OWNER='admin' AIRFLOW_CTX_DAG_ID='youtube_comments_score' AIRFLOW_CTX_TASK_ID='get_data' AIRFLOW_CTX_EXECUTION_DATE='2023-10-28T15:39:44.500439+00:00' AIRFLOW_CTX_TRY_NUMBER='2' AIRFLOW_CTX_DAG_RUN_ID='manual__2023-10-28T15:39:44.500439+00:00'
[2023-10-28T21:09:21.264+0500] {subprocess.py:63} INFO - Tmp dir root location: /tmp
[2023-10-28T21:09:21.264+0500] {subprocess.py:75} INFO - Running command: ['/usr/bin/bash', '-c', 'python3 /home/xflow/project/scripts/get_data.py']
[2023-10-28T21:09:21.269+0500] {subprocess.py:86} INFO - Output:
[2023-10-28T21:09:21.283+0500] {subprocess.py:93} INFO - python3: can't open file '/home/xflow/project/scripts/get_data.py': [Errno 2] No such file or directory
[2023-10-28T21:09:21.285+0500] {subprocess.py:97} INFO - Command exited with return code 2
[2023-10-28T21:09:21.289+0500] {taskinstance.py:1937} ERROR - Task failed with exception
Traceback (most recent call last):
  File "/home/termik/project/venv/lib/python3.10/site-packages/airflow/operators/bash.py", line 210, in execute
    raise AirflowException(
airflow.exceptions.AirflowException: Bash command failed. The command returned a non-zero exit code 2.
[2023-10-28T21:09:21.291+0500] {taskinstance.py:1400} INFO - Marking task as FAILED. dag_id=youtube_comments_score, task_id=get_data, execution_date=20231028T153944, start_date=20231028T160921, end_date=20231028T160921
[2023-10-28T21:09:21.302+0500] {standard_task_runner.py:104} ERROR - Failed to execute job 10 for task get_data (Bash command failed. The command returned a non-zero exit code 2.; 6845)
[2023-10-28T21:09:21.329+0500] {local_task_job_runner.py:228} INFO - Task exited with return code 1
[2023-10-28T21:09:21.340+0500] {taskinstance.py:2778} INFO - 0 downstream tasks scheduled from follow-on schedule check
