[2023-10-28T21:56:56.869+0500] {taskinstance.py:1159} INFO - Dependencies all met for dep_context=non-requeueable deps ti=<TaskInstance: youtube_comments_score.get_data manual__2023-10-28T16:56:53.143065+00:00 [queued]>
[2023-10-28T21:56:56.873+0500] {taskinstance.py:1159} INFO - Dependencies all met for dep_context=requeueable deps ti=<TaskInstance: youtube_comments_score.get_data manual__2023-10-28T16:56:53.143065+00:00 [queued]>
[2023-10-28T21:56:56.874+0500] {taskinstance.py:1361} INFO - Starting attempt 1 of 2
[2023-10-28T21:56:56.887+0500] {taskinstance.py:1382} INFO - Executing <Task(BashOperator): get_data> on 2023-10-28 16:56:53.143065+00:00
[2023-10-28T21:56:56.890+0500] {standard_task_runner.py:57} INFO - Started process 20341 to run task
[2023-10-28T21:56:56.892+0500] {standard_task_runner.py:84} INFO - Running: ['airflow', 'tasks', 'run', 'youtube_comments_score', 'get_data', 'manual__2023-10-28T16:56:53.143065+00:00', '--job-id', '38', '--raw', '--subdir', 'DAGS_FOLDER/youtube_comments_score.py', '--cfg-path', '/tmp/tmp3_jmt9pv']
[2023-10-28T21:56:56.893+0500] {standard_task_runner.py:85} INFO - Job 38: Subtask get_data
[2023-10-28T21:56:56.918+0500] {task_command.py:416} INFO - Running <TaskInstance: youtube_comments_score.get_data manual__2023-10-28T16:56:53.143065+00:00 [running]> on host xFlow.xFlow.virtualbox.org
[2023-10-28T21:56:56.961+0500] {taskinstance.py:1662} INFO - Exporting env vars: AIRFLOW_CTX_DAG_OWNER='admin' AIRFLOW_CTX_DAG_ID='youtube_comments_score' AIRFLOW_CTX_TASK_ID='get_data' AIRFLOW_CTX_EXECUTION_DATE='2023-10-28T16:56:53.143065+00:00' AIRFLOW_CTX_TRY_NUMBER='1' AIRFLOW_CTX_DAG_RUN_ID='manual__2023-10-28T16:56:53.143065+00:00'
[2023-10-28T21:56:56.962+0500] {subprocess.py:63} INFO - Tmp dir root location: /tmp
[2023-10-28T21:56:56.962+0500] {subprocess.py:75} INFO - Running command: ['/usr/bin/bash', '-c', 'python3 /home/termik/project/scripts/get_data.py']
[2023-10-28T21:56:56.968+0500] {subprocess.py:86} INFO - Output:
[2023-10-28T21:56:58.088+0500] {subprocess.py:93} INFO - /home/termik/project/venv/lib/python3.10/site-packages/pydantic/_internal/_fields.py:128: UserWarning: Field "model_server_url" has conflict with protected namespace "model_".
[2023-10-28T21:56:58.088+0500] {subprocess.py:93} INFO - 
[2023-10-28T21:56:58.088+0500] {subprocess.py:93} INFO - You may be able to resolve this warning by setting `model_config['protected_namespaces'] = ()`.
[2023-10-28T21:56:58.088+0500] {subprocess.py:93} INFO -   warnings.warn(
[2023-10-28T21:56:58.101+0500] {subprocess.py:93} INFO - /home/termik/project/venv/lib/python3.10/site-packages/pydantic/_internal/_config.py:317: UserWarning: Valid config keys have changed in V2:
[2023-10-28T21:56:58.101+0500] {subprocess.py:93} INFO - * 'schema_extra' has been renamed to 'json_schema_extra'
[2023-10-28T21:56:58.101+0500] {subprocess.py:93} INFO -   warnings.warn(message, UserWarning)
[2023-10-28T21:57:04.727+0500] {subprocess.py:93} INFO - Traceback (most recent call last):
[2023-10-28T21:57:04.727+0500] {subprocess.py:93} INFO -   File "/home/termik/project/scripts/get_data.py", line 38, in <module>
[2023-10-28T21:57:04.728+0500] {subprocess.py:93} INFO -     with open('/home/xflow/project/datasets/data.csv', 'a') as f:
[2023-10-28T21:57:04.728+0500] {subprocess.py:93} INFO - FileNotFoundError: [Errno 2] No such file or directory: '/home/xflow/project/datasets/data.csv'
[2023-10-28T21:57:04.939+0500] {subprocess.py:97} INFO - Command exited with return code 1
[2023-10-28T21:57:04.944+0500] {taskinstance.py:1937} ERROR - Task failed with exception
Traceback (most recent call last):
  File "/home/termik/project/venv/lib/python3.10/site-packages/airflow/operators/bash.py", line 210, in execute
    raise AirflowException(
airflow.exceptions.AirflowException: Bash command failed. The command returned a non-zero exit code 1.
[2023-10-28T21:57:04.946+0500] {taskinstance.py:1400} INFO - Marking task as UP_FOR_RETRY. dag_id=youtube_comments_score, task_id=get_data, execution_date=20231028T165653, start_date=20231028T165656, end_date=20231028T165704
[2023-10-28T21:57:04.956+0500] {standard_task_runner.py:104} ERROR - Failed to execute job 38 for task get_data (Bash command failed. The command returned a non-zero exit code 1.; 20341)
[2023-10-28T21:57:04.960+0500] {local_task_job_runner.py:228} INFO - Task exited with return code 1
[2023-10-28T21:57:04.973+0500] {taskinstance.py:2778} INFO - 0 downstream tasks scheduled from follow-on schedule check
